ipex flag is deprecated, will be removed in Accelerate v1.10. From 2.7.0, PyTorch has all needed optimizations for Intel CPU and XPU.
The following values were not passed to `accelerate launch` and had defaults used instead:
	`--num_processes` was set to a value of `8`
		More than one GPU was found, enabling multi-GPU training.
		If this was unintended please pass in `--num_processes=1`.
	`--num_machines` was set to a value of `1`
	`--mixed_precision` was set to a value of `'no'`
	`--dynamo_backend` was set to a value of `'no'`
To avoid this warning pass in values for each of the problematic parameters or run `accelerate config`.
/usr/bin/python3: can't open file '/data5/wisdomjeong/Korean_Culture_QA_2025/finetuning.py': [Errno 2] No such file or directory
/usr/bin/python3: can't open file '/data5/wisdomjeong/Korean_Culture_QA_2025/finetuning.py': [Errno 2] No such file or directory
/usr/bin/python3: can't open file '/data5/wisdomjeong/Korean_Culture_QA_2025/finetuning.py': [Errno 2] No such file or directory
/usr/bin/python3: can't open file '/data5/wisdomjeong/Korean_Culture_QA_2025/finetuning.py': [Errno 2] No such file or directory
/usr/bin/python3: can't open file '/data5/wisdomjeong/Korean_Culture_QA_2025/finetuning.py': [Errno 2] No such file or directory
/usr/bin/python3: can't open file '/data5/wisdomjeong/Korean_Culture_QA_2025/finetuning.py': [Errno 2] No such file or directory
/usr/bin/python3: can't open file '/data5/wisdomjeong/Korean_Culture_QA_2025/finetuning.py': [Errno 2] No such file or directory
/usr/bin/python3: can't open file '/data5/wisdomjeong/Korean_Culture_QA_2025/finetuning.py': [Errno 2] No such file or directory
E0709 14:53:52.664000 2411293 torch/distributed/elastic/multiprocessing/api.py:874] failed (exitcode: 2) local_rank: 0 (pid: 2411491) of binary: /usr/bin/python3
Traceback (most recent call last):
  File "/data5/wisdomjeong/.local/bin/accelerate", line 8, in <module>
    sys.exit(main())
  File "/data5/wisdomjeong/.local/lib/python3.10/site-packages/accelerate/commands/accelerate_cli.py", line 50, in main
    args.func(args)
  File "/data5/wisdomjeong/.local/lib/python3.10/site-packages/accelerate/commands/launch.py", line 1190, in launch_command
    multi_gpu_launcher(args)
  File "/data5/wisdomjeong/.local/lib/python3.10/site-packages/accelerate/commands/launch.py", line 815, in multi_gpu_launcher
    distrib_run.run(args)
  File "/data5/wisdomjeong/.local/lib/python3.10/site-packages/torch/distributed/run.py", line 883, in run
    elastic_launch(
  File "/data5/wisdomjeong/.local/lib/python3.10/site-packages/torch/distributed/launcher/api.py", line 139, in __call__
    return launch_agent(self._config, self._entrypoint, list(args))
  File "/data5/wisdomjeong/.local/lib/python3.10/site-packages/torch/distributed/launcher/api.py", line 270, in launch_agent
    raise ChildFailedError(
torch.distributed.elastic.multiprocessing.errors.ChildFailedError: 
============================================================
finetuning.py FAILED
------------------------------------------------------------
Failures:
[1]:
  time      : 2025-07-09_14:53:52
  host      : gpusystem
  rank      : 1 (local_rank: 1)
  exitcode  : 2 (pid: 2411492)
  error_file: <N/A>
  traceback : To enable traceback see: https://pytorch.org/docs/stable/elastic/errors.html
[2]:
  time      : 2025-07-09_14:53:52
  host      : gpusystem
  rank      : 2 (local_rank: 2)
  exitcode  : 2 (pid: 2411493)
  error_file: <N/A>
  traceback : To enable traceback see: https://pytorch.org/docs/stable/elastic/errors.html
[3]:
  time      : 2025-07-09_14:53:52
  host      : gpusystem
  rank      : 3 (local_rank: 3)
  exitcode  : 2 (pid: 2411494)
  error_file: <N/A>
  traceback : To enable traceback see: https://pytorch.org/docs/stable/elastic/errors.html
[4]:
  time      : 2025-07-09_14:53:52
  host      : gpusystem
  rank      : 4 (local_rank: 4)
  exitcode  : 2 (pid: 2411495)
  error_file: <N/A>
  traceback : To enable traceback see: https://pytorch.org/docs/stable/elastic/errors.html
[5]:
  time      : 2025-07-09_14:53:52
  host      : gpusystem
  rank      : 5 (local_rank: 5)
  exitcode  : 2 (pid: 2411496)
  error_file: <N/A>
  traceback : To enable traceback see: https://pytorch.org/docs/stable/elastic/errors.html
[6]:
  time      : 2025-07-09_14:53:52
  host      : gpusystem
  rank      : 6 (local_rank: 6)
  exitcode  : 2 (pid: 2411497)
  error_file: <N/A>
  traceback : To enable traceback see: https://pytorch.org/docs/stable/elastic/errors.html
[7]:
  time      : 2025-07-09_14:53:52
  host      : gpusystem
  rank      : 7 (local_rank: 7)
  exitcode  : 2 (pid: 2411498)
  error_file: <N/A>
  traceback : To enable traceback see: https://pytorch.org/docs/stable/elastic/errors.html
------------------------------------------------------------
Root Cause (first observed failure):
[0]:
  time      : 2025-07-09_14:53:52
  host      : gpusystem
  rank      : 0 (local_rank: 0)
  exitcode  : 2 (pid: 2411491)
  error_file: <N/A>
  traceback : To enable traceback see: https://pytorch.org/docs/stable/elastic/errors.html
============================================================
